Workbook

Sheet Assumptions
A1: Alpha Hours financial model: assumptions
A2: Yellow cells are inputs. Every other tab is formulas off this one. Session-based plan, August 27, 2026.
A4: PRICING
A5: Price per session, premium markets | B5: 4500
A6: Price per session, standard markets | B6: 3500
A7: Sessions per year | B7: 5
A8: Cohorts per seat (enrolled = seats x this) | B8: 4
A9: Current Alpha family discount | B9: 0.05
A10: Continuation rate from sixth session, premium | B10: 5000
A11: Deposit at sign-up | B11: 500
A12: Break week price | B12: 4500
A13: VARIABLE COST PER CHILD PER SESSION
A14: Timeback license | B14: 150
A15: Extrinsic motivation model (Alpha bucks, Emporium at cost) | B15: 40
A16: Supplies | B16: 15
A17: Snacks (about $2 a weekday block x14, $4 a Saturday block x7) | B17: 30
A18: AlphaTest Showcase, per child (printed mastery map, certificate) | B18: 5
A19: Payment processing rate | B19: 0.03
A20: Local marketing | B20: 60
A21: Variable cost per child per session | B21: =B11+B12+B13+B14+B15+B16*B2+B17
A22: Variable cost per child per year | B22: =B18*B4
A23: GUIDES
A24: Guide salary, part-time, per year | B24: 50000
A25: Students per guide (ratio 1:10) | B25: 10
A26: Guide cost per enrolled child per year at even fill | B26: =B21/(B22*B5)
A27: FIXED COST PER CAMPUS PER YEAR
A28: Lead Guide | B28: 75000
A29: Campus Coordinator (50 percent role) | B29: 50000
A30: Facility (custodial, HVAC, security after hours) | B30: 45000
A31: Insurance | B31: 8000
A32: AlphaTest Showcase events, per campus per session | B32: 2000
A33: Fixed cost per campus per year | B33: =B25+B26+B27+B28+B29*B4
A34: Minimum operating cost (fixed plus two guides) | B34: =B30+2*B21
A35: Contribution per child per year before guides | B35: =(B2-B18)*B4
A36: Break-even students per campus | B36: =ROUNDUP(B31/B32,0)
A37: CENTRAL
A38: Central team, fully loaded, Year 1 | B38: 875000
A39: Central team at full network | B39: 4000000
A40: PLAN FILL BY SESSION
A41: Session 2 (Oct 19 to Dec 18, 2026) | B41: 0.6
...

Sheet Campuses
A1: Pilot campuses at capacity
A2: Enrolled = seats x cohorts. Guides = seats / 10, rounded up. William Street shares New York's coordinator.
A4: Campus | B4: Seats | C4: Shares coordinator (1 = yes) | D4: Enrolled | E4: Revenue / year | F4: Variable cost | G4: Guides | H4: Guide cost | I4: Fixed cost | J4: Site profit | K4: Margin
A5: New York, 180 Maiden Lane | B5: 100 | C5: 0 | D5: =B5*Assumptions!$B$8 | E5: =D5*Assumptions!$B$5*Assumptions!$B$7 | F5: =D5*Assumptions!$B$22 | G5: =ROUNDUP(B5/Assumptions!$B$25,0) | H5: =G5*Assumptions!$B$24 | I5: =Assumptions!$B$33-C5*Assumptions!$B$29 | J5: =E5-F5-H5-I5 | K5: =J5/E5
A6: New York, 156 William Street | B6: 30 | C6: 1 | D6: =B6*Assumptions!$B$8 | E6: =D6*Assumptions!$B$5*Assumptions!$B$7 | F6: =D6*Assumptions!$B$22 | G6: =ROUNDUP(B6/Assumptions!$B$25,0) | H6: =G6*Assumptions!$B$24 | I6: =Assumptions!$B$33-C6*Assumptions!$B$29 | J6: =E6-F6-H6-I6 | K6: =J6/E6
A7: Greenwich (Armonk) | B7: 80 | C7: 0 | D7: =B7*Assumptions!$B$8 | E7: =D7*Assumptions!$B$5*Assumptions!$B$7 | F7: =D7*Assumptions!$B$22 | G7: =ROUNDUP(B7/Assumptions!$B$25,0) | H7: =G7*Assumptions!$B$24 | I7: =Assumptions!$B$33-C7*Assumptions!$B$29 | J7: =E7-F7-H7-I7 | K7: =J7/E7
A8: Boston A | B8: 40 | C8: 0 | D8: =B8*Assumptions!$B$8 | E8: =D8*Assumptions!$B$5*Assumptions!$B$7 | F8: =D8*Assumptions!$B$22 | G8: =ROUNDUP(B8/Assumptions!$B$25,0) | H8: =G8*Assumptions!$B$24 | I8: =Assumptions!$B$33-C8*Assumptions!$B$29 | J8: =E8-F8-H8-I8 | K8: =J8/E8
A9: Boston B | B9: 100 | C9: 0 | D9: =B9*Assumptions!$B$8 | E9: =D9*Assumptions!$B$5*Assumptions!$B$7 | F9: =D9*Assumptions!$B$22 | G9: =ROUNDUP(B9/Assumptions!$B$25,0) | H9: =G9*Assumptions!$B$24 | I9: =Assumptions!$B$33-C9*Assumptions!$B$29 | J9: =E9-F9-H9-I9 | K9: =J9/E9
A10: Chicago, at launch (94 seats) | B10: 94 | C10: 0 | D10: =B10*Assumptions!$B$8 | E10: =D10*Assumptions!$B$5*Assumptions!$B$7 | F10: =D10*Assumptions!$B$22 | G10: =ROUNDUP(B10/Assumptions!$B$25,0) | H10: =G10*Assumptions!$B$24 | I10: =Assumptions!$B$33-C10*Assumptions!$B$29 | J10: =E10-F10-H10-I10 | K10: =J10/E10
A11: Chicago, from January 2027 (517 seats) | B11: 517 | C11: 0 | D11: =B11*Assumptions!$B$8 | E11: =D11*Assumptions!$B$5*Assumptions!$B$7 | F11: =D11*Assumptions!$B$22 | G11: =ROUNDUP(B11/Assumptions!$B$25,0) | H11: =G11*Assumptions!$B$24 | I11: =Assumptions!$B$33-C11*Assumptions!$B$29 | J11: =E11-F11-H11-I11 | K11: =J11/E11
A13: Launch total, Session 2 (Chicago at 94) | B13: =SUM(B5:B10) | D13: =SUM(D5:D10) | E13: =SUM(E5:E10) | F13: =SUM(F5:F10) | G13: =SUM(G5:G10) | H13: =SUM(H5:H10) | I13: =SUM(I5:I10) | J13: =SUM(J5:J10) | K13: =J13/E13
A14: Expanded total, Session 3 onward (Chicago at 517) | B14: =SUM(B5:B9,B11) | D14: =SUM(D5:D9,D11) | E14: =SUM(E5:E9,E11) | F14: =SUM(F5:F9,F11) | G14: =SUM(G5:G9,G11) | H14: =SUM(H5:H9,H11) | I14: =SUM(I5:I9,I11) | J14: =SUM(J5:J9,J11) | K14: =J14/E14
A16: New York alone (two buildings) | E16: =E5+E6 | J16: =J5+J6
A17: Revenue per session at capacity, launch / expanded | E17: =E13/Assumptions!$B$7 | J17: =J13/Assumptions!$B$7
A18: Site profit per session at capacity, launch / expanded | E18: =E14/Assumptions!$B$7 | J18: =J14/Assumptions!$B$7
A19: Expanded run rate, net after central team | J19: =J14-Assumptions!$B$38

Sheet Year 1
A1: Year 1 by session: capacity, plan, floor
A2: Session 2 runs on the launch footprint (444 seats), Sessions 3 to 5 on the expanded footprint (867 seats). Guides are hired to sold seats: per campus, seats x fill / 10, rounded up.
A4: Plan (the number the Head is held to)
A5: Session | B5: Dates | C5: Fill | D5: Seats | E5: Enrolled | F5: Revenue | G5: Variable cost | H5: Guides | I5: Guide cost | J5: Fixed cost | K5: Site profit | L5: Margin
A6: Session 2 | B6: Oct 19 to Dec 18, 2026 | C6: =Assumptions!$B$41 | D6: =Campuses!B13 | E6: =ROUND(D6*Assumptions!$B$8*C6,0) | F6: =E6*Assumptions!$B$5 | G6: =E6*Assumptions!$B$21 | H6: =SUMPRODUCT(ROUNDUP(Campuses!$B$5:$B$10*C6/Assumptions!$B$25,0)) | I6: =H6*Assumptions!$B$24/Assumptions!$B$7 | J6: =(Campuses!$I$13)/Assumptions!$B$7 | K6: =F6-G6-I6-J6 | L6: =K6/F6
A7: Session 3 | B7: Jan 4 to Feb 19, 2027 | C7: =Assumptions!$B$42 | D7: =Campuses!B14 | E7: =ROUND(D7*Assumptions!$B$8*C7,0) | F7: =E7*Assumptions!$B$5 | G7: =E7*Assumptions!$B$21 | H7: =SUMPRODUCT(ROUNDUP(Campuses!$B$5:$B$9*C7/Assumptions!$B$25,0))+ROUNDUP(Campuses!$B$11*C7/Assumptions!$B$25,0) | I7: =H7*Assumptions!$B$24/Assumptions!$B$7 | J7: =(Campuses!$I$13)/Assumptions!$B$7 | K7: =F7-G7-I7-J7 | L7: =K7/F7
A8: Session 4 | B8: Feb 24 to Apr 16, 2027 | C8: =Assumptions!$B$43 | D8: =Campuses!B14 | E8: =ROUND(D8*Assumptions!$B$8*C8,0) | F8: =E8*Assumptions!$B$5 | G8: =E8*Assumptions!$B$21 | H8: =SUMPRODUCT(ROUNDUP(Campuses!$B$5:$B$9*C8/Assumptions!$B$25,0))+ROUNDUP(Campuses!$B$11*C8/Assumptions!$B$25,0) | I8: =H8*Assumptions!$B$24/Assumptions!$B$7 | J8: =(Campuses!$I$13)/Assumptions!$B$7 | K8: =F8-G8-I8-J8 | L8: =K8/F8
A9: Session 5 | B9: Apr 26 to Jun 18, 2027 | C9: =Assumptions!$B$44 | D9: =Campuses!B14 | E9: =ROUND(D9*Assumptions!$B$8*C9,0) | F9: =E9*Assumptions!$B$5 | G9: =E9*Assumptions!$B$21 | H9: =SUMPRODUCT(ROUNDUP(Campuses!$B$5:$B$9*C9/Assumptions!$B$25,0))+ROUNDUP(Campuses!$B$11*C9/Assumptions!$B$25,0) | I9: =H9*Assumptions!$B$24/Assumptions!$B$7 | J9: =(Campuses!$I$13)/Assumptions!$B$7 | K9: =F9-G9-I9-J9 | L9: =K9/F9
A10: Year 1 total | E10: =SUM(E6:E9) | F10: =SUM(F6:F9) | G10: =SUM(G6:G9) | I10: =SUM(I6:I9) | J10: =SUM(J6:J9) | K10: =SUM(K6:K9) | L10: =K10/F10
A11: Central team (charged in full) | K11: =-Assumptions!$B$38
A12: Net | K12: =K10+K11
A14: Capacity (every seat sold)
A15: Session | B15: Dates | C15: Fill | D15: Seats | E15: Enrolled | F15: Revenue | G15: Variable cost | H15: Guides | I15: Guide cost | J15: Fixed cost | K15: Site profit | L15: Margin
A16: Session 2 | B16: Oct 19 to Dec 18, 2026 | C16: 1 | D16: =Campuses!B13 | E16: =ROUND(D16*Assumptions!$B$8*C16,0) | F16: =E16*Assumptions!$B$5 | G16: =E16*Assumptions!$B$21 | H16: =SUMPRODUCT(ROUNDUP(Campuses!$B$5:$B$10*C16/Assumptions!$B$25,0)) | I16: =H16*Assumptions!$B$24/Assumptions!$B$7 | J16: =(Campuses!$I$13)/Assumptions!$B$7 | K16: =F16-G16-I16-J16 | L16: =K16/F16
A17: Session 3 | B17: Jan 4 to Feb 19, 2027 | C17: 1 | D17: =Campuses!B14 | E17: =ROUND(D17*Assumptions!$B$8*C17,0) | F17: =E17*Assumptions!$B$5 | G17: =E17*Assumptions!$B$21 | H17: =SUMPRODUCT(ROUNDUP(Campuses!$B$5:$B$9*C17/Assumptions!$B$25,0))+ROUNDUP(Campuses!$B$11*C17/Assumptions!$B$25,0) | I17: =H17*Assumptions!$B$24/Assumptions!$B$7 | J17: =(Campuses!$I$13)/Assumptions!$B$7 | K17: =F17-G17-I17-J17 | L17: =K17/F17
A18: Session 4 | B18: Feb 24 to Apr 16, 2027 | C18: 1 | D18: =Campuses!B14 | E18: =ROUND(D18*Assumptions!$B$8*C18,0) | F18: =E18*Assumptions!$B$5 | G18: =E18*Assumptions!$B$21 | H18: =SUMPRODUCT(ROUNDUP(Campuses!$B$5:$B$9*C18/Assumptions!$B$25,0))+ROUNDUP(Campuses!$B$11*C18/Assumptions!$B$25,0) | I18: =H18*Assumptions!$B$24/Assumptions!$B$7 | J18: =(Campuses!$I$13)/Assumptions!$B$7 | K18: =F18-G18-I18-J18 | L18: =K18/F18
A19: Session 5 | B19: Apr 26 to Jun 18, 2027 | C19: 1 | D19: =Campuses!B14 | E19: =ROUND(D19*Assumptions!$B$8*C19,0) | F19: =E19*Assumptions!$B$5 | G19: =E19*Assumptions!$B$21 | H19: =SUMPRODUCT(ROUNDUP(Campuses!$B$5:$B$9*C19/Assumptions!$B$25,0))+ROUNDUP(Campuses!$B$11*C19/Assumptions!$B$25,0) | I19: =H19*Assumptions!$B$24/Assumptions!$B$7 | J19: =(Campuses!$I$13)/Assumptions!$B$7 | K19: =F19-G19-I19-J19 | L19: =K19/F19
A20: Year 1 total | E20: =SUM(E16:E19) | F20: =SUM(F16:F19) | G20: =SUM(G16:G19) | I20: =SUM(I16:I19) | J20: =SUM(J16:J19) | K20: =SUM(K16:K19) | L20: =K20/F20
A21: Central team (charged in full) | K21: =-Assumptions!$B$38
A22: Net | K22: =K20+K21
A24: Floor (25 percent fill all year)
A25: Session | B25: Dates | C25: Fill | D25: Seats | E25: Enrolled | F25: Revenue | G25: Variable cost | H25: Guides | I25: Guide cost | J25: Fixed cost | K25: Site profit | L25: Margin
A26: Session 2 | B26: Oct 19 to Dec 18, 2026 | C26: =Assumptions!$B$45 | D26: =Campuses!B13 | E26: =ROUND(D26*Assumptions!$B$8*C26,0) | F26: =E26*Assumptions!$B$5 | G26: =E26*Assumptions!$B$21 | H26: =SUMPRODUCT(ROUNDUP(Campuses!$B$5:$B$10*C26/Assumptions!$B$25,0)) | I26: =H26*Assumptions!$B$24/Assumptions!$B$7 | J26: =(Campuses!$I$13)/Assumptions!$B$7 | K26: =F26-G26-I26-J26 | L26: =K26/F26
A27: Session 3 | B27: Jan 4 to Feb 19, 2027 | C27: =Assumptions!$B$45 | D27: =Campuses!B14 | E27: =ROUND(D27*Assumptions!$B$8*C27,0) | F27: =E27*Assumptions!$B$5 | G27: =E27*Assumptions!$B$21 | H27: =SUMPRODUCT(ROUNDUP(Campuses!$B$5:$B$9*C27/Assumptions!$B$25,0))+ROUNDUP(Campuses!$B$11*C27/Assumptions!$B$25,0) | I27: =H27*Assumptions!$B$24/Assumptions!$B$7 | J27: =(Campuses!$I$13)/Assumptions!$B$7 | K27: =F27-G27-I27-J27 | L27: =K27/F27
A28: Session 4 | B28: Feb 24 to Apr 16, 2027 | C28: =Assumptions!$B$45 | D28: =Campuses!B14 | E28: =ROUND(D28*Assumptions!$B$8*C28,0) | F28: =E28*Assumptions!$B$5 | G28: =E28*Assumptions!$B$21 | H28: =SUMPRODUCT(ROUNDUP(Campuses!$B$5:$B$9*C28/Assumptions!$B$25,0))+ROUNDUP(Campuses!$B$11*C28/Assumptions!$B$25,0) | I28: =H28*Assumptions!$B$24/Assumptions!$B$7 | J28: =(Campuses!$I$13)/Assumptions!$B$7 | K28: =F28-G28-I28-J28 | L28: =K28/F28
A29: Session 5 | B29: Apr 26 to Jun 18, 2027 | C29: =Assumptions!$B$45 | D29: =Campuses!B14 | E29: =ROUND(D29*Assumptions!$B$8*C29,0) | F29: =E29*Assumptions!$B$5 | G29: =E29*Assumptions!$B$21 | H29: =SUMPRODUCT(ROUNDUP(Campuses!$B$5:$B$9*C29/Assumptions!$B$25,0))+ROUNDUP(Campuses!$B$11*C29/Assumptions!$B$25,0) | I29: =H29*Assumptions!$B$24/Assumptions!$B$7 | J29: =(Campuses!$I$13)/Assumptions!$B$7 | K29: =F29-G29-I29-J29 | L29: =K29/F29
A30: Year 1 total | E30: =SUM(E26:E29) | F30: =SUM(F26:F29) | G30: =SUM(G26:G29) | I30: =SUM(I26:I29) | J30: =SUM(J26:J29) | K30: =SUM(K26:K29) | L30: =K30/F30
A31: Central team (charged in full) | K31: =-Assumptions!$B$38
A32: Net | K32: =K30+K31
A34: Summary
A35: Case | F35: Revenue | K35: Site profit | L35: Net
A36: Capacity | F36: =F20 | K36: =K20 | L36: =K22
A37: Plan | F37: =F10 | K37: =K10 | L37: =K12
A38: Floor | F38: =F30 | K38: =K30 | L38: =K32

Sheet 100-seat campus
A1: A 100-seat campus at capacity, line by line, per year
A2: Change the seats in B4 to see any campus.
A4: Seats | B4: 100
A5: Enrolled | B5: =B4*Assumptions!$B$8
A7: Revenue | B7: =B5*Assumptions!$B$5*Assumptions!$B$7
A8: Timeback | B8: =-B5*Assumptions!$B$14*Assumptions!$B$7
A9: Extrinsic motivation model (Emporium) | B9: =-B5*Assumptions!$B$15*Assumptions!$B$7
A10: Supplies | B10: =-B5*Assumptions!$B$16*Assumptions!$B$7
A11: Snacks | B11: =-B5*Assumptions!$B$17*Assumptions!$B$7
A12: AlphaTest Showcase (per child reports plus campus events) | B12: =-(B5*Assumptions!$B$18*Assumptions!$B$7+Assumptions!$B$32*Assumptions!$B$7)
A13: Payment processing | B13: =-B7*Assumptions!$B$19
A14: Local marketing | B14: =-B5*Assumptions!$B$20*Assumptions!$B$7
A15: Guides (seats / 10, rounded up, at guide salary) | B15: =-ROUNDUP(B4/Assumptions!$B$25,0)*Assumptions!$B$24
A16: Lead Guide | B16: =-Assumptions!$B$28
A17: Campus Coordinator | B17: =-Assumptions!$B$29
A18: Facility | B18: =-Assumptions!$B$30
A19: Insurance | B19: =-Assumptions!$B$31
A21: Total cost | B21: =SUM(B8:B19)
A22: Site profit | B22: =B7+B21
A23: Margin | B23: =B22/B7
A25: Motivation model, snacks and showcase together | B25: =-(B9+B11+B12)
A26: As a share of revenue | B26: =B25/B7

Sheet Sensitivity
A1: Sensitivity on the expanded footprint (867 seats), annual
A4: Fill
A5: Fill | B5: Enrolled | C5: Revenue | D5: Variable cost | E5: Guides | F5: Guide cost | G5: Fixed cost | H5: Site profit | I5: Net after central | J5: Margin
A6: 0.25 | B6: =ROUND(Campuses!$B$14*Assumptions!$B$8*A6,0) | C6: =B6*Assumptions!$B$5*Assumptions!$B$7 | D6: =B6*Assumptions!$B$22 | E6: =SUMPRODUCT(ROUNDUP(Campuses!$B$5:$B$9*A6/Assumptions!$B$25,0))+ROUNDUP(Campuses!$B$11*A6/Assumptions!$B$25,0) | F6: =E6*Assumptions!$B$24 | G6: =Campuses!$I$14 | H6: =C6-D6-F6-G6 | I6: =H6-Assumptions!$B$38 | J6: =H6/C6
A7: 0.5 | B7: =ROUND(Campuses!$B$14*Assumptions!$B$8*A7,0) | C7: =B7*Assumptions!$B$5*Assumptions!$B$7 | D7: =B7*Assumptions!$B$22 | E7: =SUMPRODUCT(ROUNDUP(Campuses!$B$5:$B$9*A7/Assumptions!$B$25,0))+ROUNDUP(Campuses!$B$11*A7/Assumptions!$B$25,0) | F7: =E7*Assumptions!$B$24 | G7: =Campuses!$I$14 | H7: =C7-D7-F7-G7 | I7: =H7-Assumptions!$B$38 | J7: =H7/C7
A8: 0.75 | B8: =ROUND(Campuses!$B$14*Assumptions!$B$8*A8,0) | C8: =B8*Assumptions!$B$5*Assumptions!$B$7 | D8: =B8*Assumptions!$B$22 | E8: =SUMPRODUCT(ROUNDUP(Campuses!$B$5:$B$9*A8/Assumptions!$B$25,0))+ROUNDUP(Campuses!$B$11*A8/Assumptions!$B$25,0) | F8: =E8*Assumptions!$B$24 | G8: =Campuses!$I$14 | H8: =C8-D8-F8-G8 | I8: =H8-Assumptions!$B$38 | J8: =H8/C8
A9: 1 | B9: =ROUND(Campuses!$B$14*Assumptions!$B$8*A9,0) | C9: =B9*Assumptions!$B$5*Assumptions!$B$7 | D9: =B9*Assumptions!$B$22 | E9: =SUMPRODUCT(ROUNDUP(Campuses!$B$5:$B$9*A9/Assumptions!$B$25,0))+ROUNDUP(Campuses!$B$11*A9/Assumptions!$B$25,0) | F9: =E9*Assumptions!$B$24 | G9: =Campuses!$I$14 | H9: =C9-D9-F9-G9 | I9: =H9-Assumptions!$B$38 | J9: =H9/C9
A12: Price (at capacity; processing scales with price)
A13: Session price | B13: Enrolled | C13: Revenue | D13: Variable cost | F13: Guide cost | G13: Fixed cost | H13: Site profit | I13: Net after central | J13: Margin
A14: 3500 | B14: =Campuses!$D$14 | C14: =B14*A14*Assumptions!$B$7 | D14: =B14*(Assumptions!$B$21-Assumptions!$B$19*Assumptions!$B$5+Assumptions!$B$19*A14)*Assumptions!$B$7 | F14: =Campuses!$H$14 | G14: =Campuses!$I$14 | H14: =C14-D14-F14-G14 | I14: =H14-Assumptions!$B$38 | J14: =H14/C14
A15: 4000 | B15: =Campuses!$D$14 | C15: =B15*A15*Assumptions!$B$7 | D15: =B15*(Assumptions!$B$21-Assumptions!$B$19*Assumptions!$B$5+Assumptions!$B$19*A15)*Assumptions!$B$7 | F15: =Campuses!$H$14 | G15: =Campuses!$I$14 | H15: =C15-D15-F15-G15 | I15: =H15-Assumptions!$B$38 | J15: =H15/C15
A16: 4500 | B16: =Campuses!$D$14 | C16: =B16*A16*Assumptions!$B$7 | D16: =B16*(Assumptions!$B$21-Assumptions!$B$19*Assumptions!$B$5+Assumptions!$B$19*A16)*Assumptions!$B$7 | F16: =Campuses!$H$14 | G16: =Campuses!$I$14 | H16: =C16-D16-F16-G16 | I16: =H16-Assumptions!$B$38 | J16: =H16/C16
A17: 5000 | B17: =Campuses!$D$14 | C17: =B17*A17*Assumptions!$B$7 | D17: =B17*(Assumptions!$B$21-Assumptions!$B$19*Assumptions!$B$5+Assumptions!$B$19*A17)*Assumptions!$B$7 | F17: =Campuses!$H$14 | G17: =Campuses!$I$14 | H17: =C17-D17-F17-G17 | I17: =H17-Assumptions!$B$38 | J17: =H17/C17
A18: 5500 | B18: =Campuses!$D$14 | C18: =B18*A18*Assumptions!$B$7 | D18: =B18*(Assumptions!$B$21-Assumptions!$B$19*Assumptions!$B$5+Assumptions!$B$19*A18)*Assumptions!$B$7 | F18: =Campuses!$H$14 | G18: =Campuses!$I$14 | H18: =C18-D18-F18-G18 | I18: =H18-Assumptions!$B$38 | J18: =H18/C18
A20: Every $500 on the session price, at capacity | C20: =Campuses!$D$14*500*Assumptions!$B$7*(1-Assumptions!$B$19)

Sheet Lanes
A1: Revenue by lane at expanded capacity
A2: The plan is sized on Stay. Mix is an assumption Session 2 replaces.
A4: Lane | B4: Share | C4: Families | D4: Session revenue / year | E4: Value beyond the session fee (modeled) | F4: Basis
A5: Stay (the business) | B5: =Assumptions!$B$47 | C5: =ROUND(Campuses!$D$14*B5,0) | D5: =C5*Assumptions!$B$5*Assumptions!$B$7 | E5: =C5*(Assumptions!$B$5*Assumptions!$B$7*1+Assumptions!$B$10*Assumptions!$B$7*2) | F5: Three years: year one at list, years two and three at the continuation rate
A6: Considering (upside) | B6: =Assumptions!$B$48 | C6: =ROUND(Campuses!$D$14*B6,0) | D6: =C6*Assumptions!$B$5*Assumptions!$B$7 | E6: =C6*(Assumptions!$B$5*2+0.2*Assumptions!$B$51) | F6: Two sessions plus a 20 percent conversion at the lifetime tuition midpoint
A7: Path to yes (upside) | B7: =Assumptions!$B$49 | C7: =ROUND(Campuses!$D$14*B7,0) | D7: =C7*Assumptions!$B$5*Assumptions!$B$7 | E7: =C7*(Assumptions!$B$5*3+0.2*Assumptions!$B$51) | F7: Three sessions plus a 20 percent admit rate at the lifetime tuition midpoint
A8: Current Alpha families | B8: =Assumptions!$B$50 | C8: =ROUND(Campuses!$D$14*B8,0) | D8: =C8*Assumptions!$B$5*Assumptions!$B$7*(1-Assumptions!$B$9) | F8: Retention of a family already paying full tuition
A9: Total | B9: =SUM(B5:B8) | C9: =SUM(C5:C8) | D9: =SUM(D5:D8)
A11: Feeder sensitivity (upside), expanded pilot base
A12: Conversion rate | B12: Enrollments | C12: Lifetime tuition
A13: 0.04 | B13: =ROUND(Campuses!$D$14*A13,0) | C13: =B13*Assumptions!$B$51
A14: 0.08 | B14: =ROUND(Campuses!$D$14*A14,0) | C14: =B14*Assumptions!$B$51
A15: 0.12 | B15: =ROUND(Campuses!$D$14*A15,0) | C15: =B15*Assumptions!$B$51

Sheet National
A1: The national build, capacity figures, K-8 blocks, premium price
A4: Wave | B4: Session | C4: Campuses added | D4: Campuses (count) | E4: Seats added | F4: Enrolled added | G4: Run rate added | H4: Network run rate
A5: Pilot | B5: Session 2, Oct 2026 | C5: New York (2), Greenwich, Boston (2), Chicago | D5: 6 | E5: =Campuses!B13 | F5: =E5*Assumptions!$B$8 | G5: =F5*Assumptions!$B$5*Assumptions!$B$7 | H5: =SUM($G$5:G5)
A6: Wave 2 | B6: Session 3, Jan 2027 | C6: Chicago expansion (+423), Austin 300, Miami 150, Palm Beach 60, Miami Beach 50 | D6: 4 | E6: =423+300+150+60+50 | F6: =E6*Assumptions!$B$8 | G6: =F6*Assumptions!$B$5*Assumptions!$B$7 | H6: =SUM($G$5:G6)
A7: Wave 3 | B7: Session 4, Feb 2027 | C7: Every remaining campus, about 30, at 50 seats each | D7: 30 | E7: =30*50 | F7: =E7*Assumptions!$B$8 | G7: =F7*Assumptions!$B$5*Assumptions!$B$7 | H7: =SUM($G$5:G7)
A9: Full network at capacity
A10: Campuses | B10: =SUM(D5:D7)
A11: Seats | B11: =SUM(E5:E7)
A12: Enrolled | B12: =SUM(F5:F7)
A13: Revenue | B13: =B12*Assumptions!$B$5*Assumptions!$B$7
A14: Variable cost | B14: =-B12*Assumptions!$B$22
A15: Guide cost | B15: =-ROUNDUP(B11/Assumptions!$B$25,0)*Assumptions!$B$24
A16: Fixed cost | B16: =-B10*Assumptions!$B$33
A17: Site profit | B17: =B13+B14+B15+B16
A18: Margin | B18: =B17/B13
A19: Central team at full network | B19: =-Assumptions!$B$39
A20: Net | B20: =B17+B19
A22: Three-year view (network held at 40 campuses; evening block and break weeks as additions)
A23: Year | B23: K-8 fill | C23: K-8 revenue | D23: Evening block share of its ceiling | E23: Evening block revenue | F23: Break weeks share | G23: Break week revenue (2 weeks) | H23: Total revenue | I23: Net (about, at network margin)
A24: Year 2, SY27-28 | B24: 0.75 | C24: =$B$13*B24 | D24: 0.4 | E24: =$B$13*0.5*D24 | F24: 0.6 | G24: =$B$11*2*Assumptions!$B$12*F24 | H24: =C24+E24+G24 | I24: =H24*$B$18-Assumptions!$B$39
A25: Year 3, SY28-29 | B25: 0.9 | C25: =$B$13*B25 | D25: 0.7 | E25: =$B$13*0.5*D25 | F25: 0.8 | G25: =$B$11*2*Assumptions!$B$12*F25 | H25: =C25+E25+G25 | I25: =H25*$B$18-Assumptions!$B$39

Sheet Launch budget
A1: One-time launch budget, before Session 2
A4: Item | B4: Basis | C4: Cost
A5: Guide training cohort | B5: 45 guides and 6 Lead Guides, two paid weeks at the part-time rate | C5: =(Campuses!G13+6)*Assumptions!$B$24/52*2
A6: State exemption filings and legal | B6: New York, Connecticut, Massachusetts, Illinois | C6: 60000
A7: Launch marketing | B7: $40K per market, four markets | C7: 160000
A8: Loaner device pool | B8: 20 percent of launch seats at $600 | C8: =Campuses!B13*0.2*600
A9: Insurance deposits | B9: Six sites | C9: 24000
A10: Emporium opening inventory | B10: $25 a seat | C10: =Campuses!B13*25
A11: Registration and payments stack | B11: Stripe, HubSpot, roster tooling | C11: 30000
A12: Total | C12: =SUM(C5:C11)
A14: Session 2 deposits on plan enrollment | C14: ='Year 1'!E6*Assumptions!$B$11
A15: Deposits cover the launch budget | C15: =IF(C14>=C12,"Yes","No")
